Workbook

Sheet CharacterData
A1: 캐릭터 아이디 | B1: 캐릭터 타입 | C1: 한국이름 | D1: 영어이름 | E1: 설명 | F1: 종족 타입(종족 공통 숙련도) | G1: 진영 타입 | H1: 초기 레벨 | I1: 체력 | J1: 공격력 | K1: 방어력 | L1: 공격속도 > 0 | M1: 사거리 1 > | N1: 크리티컬 | O1: 명중률 > 0 | P1: 회피 | Q1: 힘(무게 감당) | R1: 속도 | S1: 숙련도 이름 | T1: 숙련도 초기 레벨 | U1: 숙련도 적용 수치 | V1: 초기 스킬 ID | W1: 초기 스킬 레벨 | X1: 리깅 타입 | Y1: 시작 아이템 | Z1: 시작 아이템 갯수
A2: int | B2: Enum<CharacterType> | C2: string | D2: string | E2: string | F2: Enum<BloodType> | G2: Enum<VillageType> | H2: int | I2: float | J2: float | K2: float | L2: float | M2: float | N2: float | O2: float | P2: float | Q2: int | R2: float | S2: List<Enum<Ability>> | T2: List<int> | U2: List<float> | V2: List<int> | W2: List<int> | X2: Enum<RiggingType> | Y2: List<int> | Z2: List<int>
A3: characterID | B3: characterType | C3: name_kr | D3: name_en | E3: description | F3: bloodType | G3: familyType | H3: Level | I3: health | J3: damage | K3: defence | L3: attackSpeed | M3: attackRange | N3: criticalPercent | O3: aimPercent | P3: missPercent | Q3: force | R3: moveSpeed | S3: abilityName | T3: abilityInitLevel | U3: abilityValue | V3: SkillListID | W3: SkillListLevel | X3: RiggingType | Y3: StartItem | Z3: StartItemCount
A4: 1 | B4: player | C4: 백성은 | D4: seongeun | E4: 손재주가 뛰어나지만 전투에는 약한 모습을 보인다 | F4: Person | G4: CasinoVill | H4: 1 | I4: 100 | J4: 5 | K4: 5 | L4: 1 | M4: 1 | N4: 1 | O4: 1 | P4: 1 | Q4: 500 | R4: 10 | S4: Run| Regeneration| Make | T4: 3| 3| 3 | U4: 3| 3| 4 | V4: 4001 | W4: 1 | Y4: 0 | Z4: 0
A5: 2 | B5: player | C5: 최종현 | D5: choijonghyun | E5: 드래곤은 뛰어난 회복력을 가지고 있으며 다른 종족에 비해 모든 능력이 높지만 성장이 느리다. | F5: Dragon | G5: DragonRare | H5: 1 | I5: 500 | J5: 40 | K5: 10 | L5: 0.7 | M5: 3 | N5: 10 | O5: 1 | P5: 1 | Q5: 1000 | R5: 12 | S5: None | T5: 3 | U5: 4 | V5: 4001 | W5: 1 | Y5: 0 | Z5: 0
A6: 3 | B6: player | C6: 손유민 | D6: sonyumin | E6: 경찰을 털다가 쫓겨날 정도로 어리석었다. | F6: Person | G6: RookieVill | H6: 1 | I6: 200 | J6: 10 | K6: 6 | L6: 1.5 | M6: 3 | N6: 5 | O6: 100 | P6: 1.5 | Q6: 500 | R6: 5 | S6: Run| Make | T6: 3|3 | U6: 3|4 | V6: 4001 | W6: 1 | Y6: 0 | Z6: 0
A7: 4 | B7: player | C7: 가일 | D7: Guile | E7: 유망한 기사였지만 언데드와의 전쟁 중 사망하고 스켈레톤으로 다시 깨어났다. | F7: UnDead | G7: UndeadVill | H7: 1 | I7: 400 | J7: 26 | K7: 10 | L7: 0.8 | M7: 3 | N7: 3 | O7: 100 | P7: 2 | Q7: 500 | R7: 5 | S7: Battle| Run| UnLock| Regeneration| Make | T7: 3|3|3|3|3 | U7: 3|3|3|3|4 | V7: 4001 | W7: 1 | Y7: 0 | Z7: 0
A8: 5 | B8: player | C8: 지승준 | D8: jiseungjun | E8: 눈을 떠보니 인간이였던 내가 언데드? | F8: UnDead | G8: UndeadVill | H8: 1 | I8: 100 | J8: 5 | K8: 5 | L8: 4 | M8: 4 | N8: 10 | O8: 1 | P8: 1.5 | Q8: 200 | R8: 3 | S8: Regeneration | T8: 3 | U8: 4 | V8: 4001 | W8: 1 | X8: Humanoid | Y8: 0 | Z8: 0
A9: 6 | B9: player | C9: 호저 | D9: hozer | E9: 빈민가의 좀도둑 출신. 기사를 동경하지만, 눈 앞 현실에 집중하며 살아가고 있다. | F9: Person | G9: RookieVill | H9: 1 | I9: 300 | J9: 23 | K9: 8 | L9: 1.2 | M9: 3 | N9: 8 | O9: 100 | P9: 8 | Q9: 500 | R9: 5 | S9: Still|Run | T9: 3|3 | U9: 1.2|3 | V9: 4001 | W9: 1 | X9: Humanoid | Y9: 0 | Z9: 0
A10: 7 | B10: player | C10: 밸런스맨 | D10: balance | E10: 밸런스를 잡기 위한 1포인트당 증가하는 능력치를 확인해보자(60 분배+레벨당 10) 총10개 스택 | F10: Person | G10: RookieVill | H10: 1 | I10: 20 | J10: 3 | K10: 1 | L10: 0.1 | M10: 0.1 | N10: 0.5 | O10: 0.2 | P10: 0.2 | Q10: 50 | R10: 1
A11: 701 | B11: enemy | C11: 테스트용 블럭 | D11: sonyumin | E11: 테스트용 블럭입니다 | F11: Person | G11: RookieVill | H11: 1 | I11: 200 | J11: 10 | K11: 6 | L11: 1.5 | M11: 3 | N11: 5 | O11: 100 | P11: 1.5 | Q11: 500 | R11: 36 | V11: 4001 | W11: 1 | Y11: 0 | Z11: 0
A12: 102 | B12: enemy | C12: 약탈자 | D12: sonyumin | E12: 경찰을 털다가 쫓겨날 정도로 어리석었다. | F12: Person | G12: RookieVill | H12: 1 | I12: 150 | J12: 12 | K12: 6 | L12: 1.5 | M12: 3 | N12: 5 | O12: 100 | P12: 1.5 | Q12: 501 | R12: 18 | V12: 4001 | W12: 1 | Y12: 0 | Z12: 0
A13: 103 | B13: enemy | C13: 늑대 우두머리 | D13: sonyumin | E13: 야생에 서식하는 큰 늑대다 | F13: Person | G13: RookieVill | H13: 1 | I13: 180 | J13: 12 | K13: 6 | L13: 1.5 | M13: 3 | N13: 5 | O13: 100 | P13: 1.5 | Q13: 502 | R13: 18 | V13: 4001 | W13: 1 | Y13: 0 | Z13: 0
A14: 201 | B14: enemy | C14: 들개 | D14: Wild Dog | E14: 황무지에서 흔히 볼 수 있는 사나운 들개. 무리로 공격한다 | F14: Beast | G14: RookieVill | H14: 1 | I14: 100 | J14: 11 | K14: 1 | L14: 0.7 | M14: 0.5 | N14: 2 | O14: 100 | P14: 0.5 | Q14: 100 | R14: 18 | S14: Bite|Howl | T14: 2|3 | U14: 1.1|0.5 | V14: 4001 | W14: 1 | Y14: 0 | Z14: 0
A15: 202 | B15: enemy | C15: 거미 | D15: Spider | E15: 강한 맹독과 거미줄 공격이 특징. 숲과 동굴에 분포 | F15: Beast | G15: RookieVill | H15: 1 | I15: 100 | J15: 9 | K15: 2 | L15: 0.8 | M15: 0.7 | N15: 2 | O15: 100 | P15: 0.7 | Q15: 100 | R15: 18 | S15: Poison_Bite| WebShot | T15: 2|3 | U15: 1.3|0.9 | V15: 4001 | W15: 1 | Y15: 0 | Z15: 0
A16: 203 | B16: enemy | C16: 고블린 | D16: Goblin | E16: 약하지만 숫자가 많다. 때로는 무기를 들고 다닌다. | F16: Person | G16: RookieVill | H16: 1 | I16: 120 | J16: 11 | K16: 2 | L16: 0.6 | M16: 0.5 | N16: 2 | O16: 100 | P16: 0.4 | Q16: 100 | R16: 18 | S16: Slash| Ambush | T16: 1|2 | U16: 1.0| 0.6 | V16: 4001 | W16: 1 | Y16: 0 | Z16: 0
A17: 204 | B17: enemy | C17: 슬라임 | D17: Slime | E17: 점액질 몸체로 물리 공격에 강하다. 움직임이 느리다. | F17: Elemental | G17: RookieVill | H17: 1 | I17: 100 | J17: 9 | K17: 2 | L17: 0.4 | M17: 0.5 | N17: 1 | O17: 100 | P17: 0.3 | Q17: 100 | R17: 18 | S17: Acid_Splash | T17: 2 | U17: 0.7 | V17: 4001 | W17: 1 | Y17: 0 | Z17: 0
A18: 205 | B18: enemy | C18: 스켈레톤 | D18: mutationskeleton | E18: 실험으로 인해 피아식별이 불가능해진 스켈레톤이다 | F18: UnDead | G18: UndeadVill | H18: 1 | I18: 160 | J18: 12 | K18: 5 | L18: 1 | M18: 1 | N18: 0 | O18: 100 | P18: 0 | Q18: 100 | R18: 18 | S18: None | T18: 3 | U18: 3 | V18: 4001 | W18: 1 | Y18: 0 | Z18: 0
A19: 206 | B19: enemy | C19: 늑대 | D19: wolf | E19: 야생에 서식하는 평범한 늑대다 | F19: Beast | G19: RookieVill | H19: 1 | I19: 100 | J19: 10 | K19: 1 | L19: 1 | M19: 0.5 | N19: 2 | O19: 100 | P19: 0.5 | Q19: 100 | R19: 18 | S19: Bite|Howl | T19: 2|3 | U19: 1.1|0.5 | V19: 4001 | W19: 1 | Y19: 0 | Z19: 0
A20: 301 | B20: enemy | C20: 망자 | D20: Hollow | E20: 모두에게 잊혀져 망자가 되었다. | F20: Hollow | G20: Cemetery | H20: 1 | I20: 120 | J20: 10 | K20: 1 | L20: 1 | M20: 0.5 | N20: 2 | O20: 100 | P20: 0.5 | Q20: 100 | R20: 18 | S20: Bite|Howl | T20: 2|4 | U20: 1.1|0.6 | V20: 4001 | W20: 1 | Y20: 0 | Z20: 0
A21: 302 | B21: enemy | C21: 망자 호위병 | D21: Hollowguard | E21: 라스 가문의 사람들이 망자가 되어 망자보다 강력하다, | F21: Hollow | G21: Cemetery | H21: 1 | I21: 160 | J21: 12 | K21: 1 | L21: 1 | M21: 0.5 | N21: 2 | O21: 100 | P21: 0.5 | Q21: 100 | R21: 18 | S21: Bite|Howl | T21: 2|5 | U21: 1.1|0.7 | V21: 4001 | W21: 1 | Y21: 0 | Z21: 0
A22: 401 | B22: enemy | C22: 돼지 | D22: pig | E22: 자연으로부터 살아남기 위해서 성장했다. 잘못 사냥하다가 사상자가 나오곤 한다. | F22: Beast | G22: RookieVill | H22: 1 | I22: =I10*6 -> 120 | J22: 10 | K22: 5 | L22: 1 | M22: 1 | N22: 5 | O22: 100 | P22: 0.5 | Q22: =Q10*6*6 -> 1800 | R22: 18 | S22: None | T22: 0 | U22: 0 | X22: Leg4
A23: 402 | B23: enemy | C23: 소 | D23: cow | E23: 자연으로부터 살아남기 위해서 성장했다. 잘못 사냥하다가 사상자가 나오곤 한다. | F23: Beast | G23: RookieVill | H23: 1 | I23: =I10*6 -> 120 | J23: 10 | K23: 5 | L23: 1 | M23: 1 | N23: 5 | O23: 100 | P23: 0.5 | Q23: =Q10*6*6 -> 1800 | R23: 18 | S23: None | T23: 0 | U23: 0 | X23: Leg4
A24: 403 | B24: enemy | C24: 도적 우두머리 | D24: gang_leader | E24: 도적단 내에서 가장 무력이 쌔서 우두머리 | F24: Person | G24: Gang | H24: 1 | I24: 220 | J24: 15 | K24: 5 | L24: 1 | M24: 1 | N24: 5 | O24: 100 | P24: 0.5 | Q24: =Q10*6*6 -> 1800 | R24: 18 | X24: Humanoid
A25: 404 | B25: enemy | C25: 도적 | D25: gang | E25: 무력으로 쉽게 살아가려는 이들. | F25: Person | G25: Gang | H25: 1 | I25: =I10*6 -> 120 | J25: 12 | K25: 5 | L25: 1 | M25: 1 | N25: 5 | O25: 100 | P25: 0.5 | Q25: =Q10*6*4 -> 1200 | R25: 18 | X25: Humanoid
A26: 501 | B26: npc | C26: 무기상인 | D26: Chars | E26: 무기상인 | F26: Person | G26: RookieVill | H26: 1 | I26: 200 | J26: 10 | K26: 6 | L26: 1.5 | M26: 3 | N26: 5 | O26: 100 | P26: 0.5 | Q26: 503 | R26: 5 | S26: Run| Make | T26: 3|3 | U26: 3|4 | V26: 4001 | W26: 1 | Y26: 0 | Z26: 0
A27: 502 | B27: npc | C27: 오르투스 | D27: Ortus | E27: 가일을 언데드로 일으킨 네크로맨서. 가일의 성장에 흥미로워한다. | F27: Person | G27: UndeadVill | H27: 1 | I27: 200 | J27: 10 | K27: 6 | L27: 1.5 | M27: 3 | N27: 5 | O27: 100 | P27: 1.5 | Q27: 504 | R27: 5 | S27: Run| Make | T27: 3|3 | U27: 3|4 | V27: 4001 | W27: 1 | Y27: 0 | Z27: 0
A28: 503 | B28: npc | C28: 루크 | D28: Luke | E28: 전쟁 중 심각한 부상을 입은 가일의 동료 | F28: Person | G28: RookieVill | H28: 1 | I28: 1 | J28: 0 | K28: 0 | L28: 1 | M28: 1 | N28: 0 | O28: 1 | P28: 0 | Q28: 505 | R28: 0 | S28: Run| Make | T28: 3|3 | U28: 3|4 | V28: 4001 | W28: 1 | Y28: 0 | Z28: 0
A29: 504 | B29: npc | C29: 벨그라스 | D29: Belgras | E29: 강한 개체를 만들기 위해선 그 어떤짓도 서슴치않는다. 자신의 실험병기들에 대한 자부심을 가지고있고 네크로맨서가 일으킨 초기의 언데드들을 무시하는 경향이 있다. | F29: Person | G29: UndeadVill | H29: 1 | I29: 200 | J29: 10 | K29: 6 | L29: 1.5 | M29: 3 | N29: 5 | O29: 100 | P29: 1.5 | Q29: 506 | R29: 5 | S29: Run| Make | T29: 3|3 | U29: 3|4 | V29: 4001 | W29: 1 | Y29: 0 | Z29: 0
A30: 505 | B30: npc | C30: 병사 | D30: soldier | E30: 왕국의 병사 | F30: Person | G30: RookieVill | H30: 1 | I30: 50 | J30: 5 | K30: 5 | L30: 1 | M30: 1 | N30: 0 | O30: 100 | P30: 0 | Q30: 100 | R30: 3 | S30: None | T30: 3 | U30: 3 | V30: 4001 | W30: 1 | Y30: 1001|1011 | Z30: 1|1
A31: 506 | B31: npc | C31: 스켈레톤 | D31: skeleton | E31: 네크로맨서의 기초적인 병사 | F31: UnDead | G31: UndeadVill | H31: 1 | I31: 60 | J31: 6 | K31: 5 | L31: 1 | M31: 1 | N31: 0 | O31: 100 | P31: 0 | Q31: 100 | R31: 3 | S31: None | T31: 3 | U31: 3 | V31: 4001 | W31: 1 | Y31: 0 | Z31: 0
A32: 507 | B32: npc | C32: 강화상인 | D32: enhanceMan | E32: 강화NPC | F32: UnDead | G32: UndeadVill | H32: 1 | I32: 200 | J32: 5 | K32: 5 | L32: 1 | M32: 1 | N32: 0 | O32: 100 | P32: 0 | Q32: 100 | R32: 3 | S32: None | T32: 3 | U32: 3 | V32: 4001 | W32: 1 | Y32: 0 | Z32: 0
A33: 508 | B33: npc | C33: 커즈 | D33: Kurz | E33: 언데드왕국에서 인정받은 대장장이. | F33: Person | G33: UndeadVill | H33: 1 | I33: 300 | J33: 15 | K33: 10 | L33: 1 | M33: 1 | N33: 5 | O33: 100 | P33: 1 | Q33: 500 | R33: 5 | S33: Run| Make | T33: 3|10 | U33: 3|4 | V33: 4001 | W33: 1 | Y33: 0 | Z33: 0
A34: 509 | B34: npc | C34: 정찰병 | D34: Scout | E34: 인간진영의 정찰대원 | F34: Person | G34: RookieVill | H34: 1 | I34: 100 | J34: 5 | K34: 5 | L34: 1 | M34: 1 | N34: 2 | O34: 100 | P34: 0 | Q34: 100 | R34: 5 | S34: None | T34: 3 | U34: 3 | V34: 4001 | W34: 1 | Y34: 0 | Z34: 0
A35: 510 | B35: npc | C35: 정찰병대장 | D35: ScoutLeader | E35: 인간진영의 정찰대원을 이끄는 대장 | F35: Person | G35: RookieVill | H35: 1 | I35: 150 | J35: 8 | K35: 5 | L35: 1 | M35: 1 | N35: 2 | O35: 100 | P35: 0 | Q35: 100 | R35: 5 | S35: None | T35: 3 | U35: 3 | V35: 4001 | W35: 1 | Y35: 0 | Z35: 0
A36: 511 | B36: npc | C36: 네크로맨서 | D36: Necromancer | E36: 언데드진영의 네크로맨서 | F36: Person | G36: UndeadVill | H36: 1 | I36: 200 | J36: 10 | K36: 6 | L36: 1.5 | M36: 3 | N36: 5 | O36: 100 | P36: 1.5 | Q36: 504 | R36: 5 | S36: Run| Make | T36: 3|3 | U36: 3|4 | V36: 4001 | W36: 1 | Y36: 0 | Z36: 0
A37: 512 | B37: npc | C37: 플레이어시체 | D37: DeadBody | E37: 플레이어 사망 후 생성될 npc | F37: Person | G37: RookieVill | H37: 1 | I37: 0 | J37: 0 | K37: 0 | L37: 0 | M37: 0 | N37: 0 | O37: 0 | P37: 0 | Q37: 5000 | R37: 0 | S37: None | T37: 0 | U37: 0 | V37: 0 | W37: 0 | X37: Humanoid | Y37: 0 | Z37: 0
A38: 513 | B38: npc | C38: 소비상인 | D38: consumptionMan | E38: 소비상인이다 | F38: Person | G38: RookieVill | H38: 1 | I38: 200 | J38: 10 | K38: 6 | L38: 1.5 | M38: 3 | N38: 5 | O38: 100 | P38: 1.5 | Q38: 503 | R38: 5 | S38: Run| Make | T38: 3|3 | U38: 3|4 | V38: 4001 | W38: 1 | Y38: 0 | Z38: 0
A39: 514 | B39: npc | C39: 방어구상인 | D39: ArmorMan | E39: 방어구를 판매하는 상인이다. | F39: Person | G39: RookieVill | H39: 1 | I39: 200 | J39: 10 | K39: 6 | L39: 1.5 | M39: 3 | N39: 5 | O39: 100 | P39: 1.5 | Q39: 503 | R39: 5 | S39: Run| Make | T39: 3|3 | U39: 3|4 | V39: 4001 | W39: 1 | X39: Humanoid | Y39: 0 | Z39: 0
A40: 601 | B40: npc | C40: 이벨트 | D40: Ibelteu | E40: 정체불명의 망자로 플레이어를 도와준다. | F40: Hollow | G40: Cemetery | H40: 1 | V40: 4001 | W40: 1 | Y40: 0 | Z40: 0
...

Sheet PlayerData
A1: 캐릭터 아이디 | B1: 숙련도 성장 경험치 보정 | C1: 숙련도 맥스 레벨 | D1: 배고픔 | E1: 목마름 | F1: 초기 레벨 | G1: 한계 레벨 | H1: 레벨마다 추가 성장치 | I1: 필요 경험치 | J1: 메인퀘ID | K1: 체력성장치 | L1: 공격력성장치 | M1: 방어력성장치 | N1: 공격속도 성장치 | O1: 크리티컬성장치 | P1: 명중률성장치 | Q1: 회피성장치 | R1: 걷는 속도 성장치 | S1: 힘 성장치 | T1: 선행 퀘스트 발행
A2: int | B2: List<float> | C2: List<int> | D2: float | E2: float | F2: int | G2: int | H2: float | I2: float | J2: int | K2: float | L2: float | M2: float | N2: float | O2: float | P2: float | Q2: float | R2: float | S2: int | T2: int
A3: characterID | B3: abilityExpWeight | C3: abilityMaxLevel | D3: hungry | E3: thirsty | F3: initLevel | G3: maxLevel | H3: levelWeight | I3: exp | J3: questID | K3: health | L3: damage | M3: defence | N3: attackSpeed | O3: criticalPercent | P3: aimPercent | Q3: missPercent | R3: moveSpeed | S3: force | T3: preQuestID
A4: 1 | B4: 1.5|1.5|1.5|1.5 | C4: 20|20|20|20 | D4: 100 | E4: 100 | F4: 1 | G4: 40 | H4: 0.03 | I4: 20 | K4: 100 | L4: 5 | M4: 5 | N4: 1 | R4: 10 | S4: 500 | T4: 100001
A5: 2 | B5: 0.5| 0.5 | C5: 20|20 | D5: 100 | E5: 100 | F5: 1 | G5: 40 | H5: 0.03 | I5: 20 | K5: 500 | L5: 40 | M5: 10 | N5: 0.7 | O5: 10 | P5: 1 | Q5: 1 | R5: 12 | S5: 1000 | T5: 100002
A6: 3 | B6: 1.8| 1.8| 1.2 | C6: 20| 20| 20 | D6: 100 | E6: 100 | F6: 1 | G6: 40 | H6: 0.03 | I6: 20 | K6: 200 | L6: 10 | M6: 6 | N6: 1.5 | O6: 5 | P6: 100 | Q6: 1.5 | R6: 5 | S6: 500 | T6: 100003
A7: 4 | B7: 1.8| 1.2| 0.5| 1.5| 1.5| 1| 1.8| 0.8| 1| 1 | C7: 20|20|20|20|20|20|20|20|20|20 | D7: 100 | E7: 100 | F7: 1 | G7: 40 | H7: 0.03 | I7: 20 | K7: 300 | L7: 20 | M7: 8 | N7: 0.8 | O7: 0 | P7: 0.7 | Q7: 0.5 | R7: 5 | S7: 400 | T7: 100004
A8: 5 | B8: 1.5| 1.5 | C8: 20| 20 | D8: 100 | E8: 100 | F8: 1 | G8: 40 | H8: 0.03 | I8: 20 | K8: 100 | L8: 5 | M8: 3 | N8: 4 | O8: 10 | P8: 1 | Q8: 1.5 | R8: 3 | S8: 200 | T8: 100005
A9: 6 | B9: 1.2|1.2 | C9: 30|30 | D9: 100 | E9: 100 | F9: 1 | G9: 40 | H9: 0.1 | I9: 20 | K9: =CharacterData!I10 -> 20 | L9: =CharacterData!J10 -> 3 | M9: =CharacterData!K10 -> 1 | N9: =CharacterData!L10 -> 0.1 | O9: =CharacterData!M10 -> 0.1 | P9: =CharacterData!N10 -> 0.5 | Q9: =CharacterData!O10 -> 0.2 | R9: =CharacterData!P10 -> 0.2 | S9: =CharacterData!Q10 -> 50 | T9: 100006

Sheet EnemyData
A1: 캐릭터 아이디 | B1: 선공몹 | C1: 감지 범위 | D1: 이동 범위 | E1: 공격 시야각 | F1: 소환 위치 | G1: 드랍아이템 | H1: 드랍확률 | I1: 드랍갯수 | J1: 드랍골드최소치 | K1: 드랍골드최대치
A2: int | B2: bool | C2: float | D2: float | E2: float | F2: List<Enum<PlaceType>> | G2: List<int> | H2: List<float> | I2: List<int> | J2: int | K2: int
A3: characterID | B3: isFirst | C3: targetingRange | D3: wanderMoveRange | E3: AttackRange | F3: spawnPlace | G3: DropItemIDs | H3: DropRates | I3: DropCounts | J3: DropGoldMin | K3: DropGoldMax
A4: 101 | B4: TRUE | C4: 8.5 | D4: 5.5 | E4: 120 | F4: Field
A5: 102 | B5: TRUE | C5: 8.5 | D5: 5.5 | E5: 120 | F5: Field | G5: 2212|3004 | H5: 20|50 | I5: 1|1 | J5: 0 | K5: 10
A6: 103 | B6: TRUE | C6: 8.5 | D6: 5.5 | E6: 120 | F6: Field | G6: 2212|3004 | H6: 20|50 | I6: 1|1 | J6: 0 | K6: 10
A7: 201 | B7: TRUE | C7: 8.5 | D7: 5.5 | E7: 120 | F7: Field | G7: 2212|3004 | H7: 20|50 | I7: 1|1 | J7: 0 | K7: 0
A8: 202 | B8: TRUE | C8: 8.5 | D8: 5.5 | E8: 120 | F8: Field | J8: 5 | K8: 10
A9: 203 | B9: TRUE | C9: 8.5 | D9: 5.5 | E9: 120 | F9: Field | G9: 2212|2203|3004 | H9: 20|20|50 | I9: 1|1|1 | J9: 0 | K9: 10
A10: 204 | B10: TRUE | C10: 8.5 | D10: 5.5 | E10: 120 | F10: Field | G10: 2210 | H10: 30 | I10: 1 | J10: 0 | K10: 0
A11: 205 | B11: FALSE | C11: 8.5 | D11: 5.5 | E11: 120 | F11: Field | J11: 10 | K11: 15
A12: 206 | B12: FALSE | C12: 8.5 | D12: 5.5 | E12: 120 | F12: Field | G12: 2212|3004 | H12: 20|50 | I12: 1|1 | J12: 0 | K12: 0
A13: 301 | B13: TRUE | C13: 8.5 | D13: 5.5 | E13: 120 | F13: Field | J13: 10 | K13: 15
A14: 302 | B14: TRUE | C14: 8.5 | D14: 5.5 | E14: 120 | F14: Field | J14: 10 | K14: 20
A15: 401 | B15: FALSE | C15: 17 | D15: 3 | E15: 120 | F15: Field | G15: 2201|3004 | H15: 20|50 | I15: 1|1 | J15: 0 | K15: 0
A16: 402 | B16: FALSE | C16: 17 | D16: 3 | E16: 120 | F16: Field | G16: 2202|3004 | H16: 20|50 | I16: 1|1 | J16: 0 | K16: 0
A17: 403 | B17: FALSE | C17: 8.5 | D17: 5.5 | E17: 120 | F17: Field | G17: 2208|2209|2211|3004 | H17: 10|10|30|50 | I17: 1|1|1|1 | J17: 5 | K17: 15
A18: 404 | B18: FALSE | C18: 8.5 | D18: 5.5 | E18: 120 | F18: Field | G18: 2208|2209|2211|3004 | H18: 10|10|30|50 | I18: 1|1|1|1 | J18: 5 | K18: 10

Sheet NPCData
A1: 캐릭터 아이디 | B1: 다이얼로그 종류 | C1: NPC 타입 | D1: 캐릭터별 고유대사
A2: int | B2: List<int> | C2: Enum<NPCType> | D2: List<string>
A3: characterID | B3: DiaglogList | C3: npcType | D3: CharacterTalk
A4: 501 | B4: 0 | C4: WeaponNPC
A5: 502 | B5: 0 | C5: None
A6: 503 | B6: 0 | C6: None
A7: 504 | B7: 0 | C7: None
A8: 505 | B8: 0 | C8: None
A9: 506 | B9: 0 | C9: None
A10: 507 | B10: 0 | C10: EnhanceNPC
A11: 508 | B11: 0 | C11: None
A12: 509 | B12: 0 | C12: None
A13: 510 | B13: 0 | C13: None
A14: 511 | B14: 0 | C14: None
A15: 512 | B15: 0 | C15: DeadBodyNPC
... A34: 817 | B34: 0 | C34: None

Sheet BloodData
A1: 종족이름 | B1: 종족 공통 숙련도 | C1: 숙련도 현재 레벨 | D1: 숙련도 적용 수치 | E1: 숙련도 맥스 레벨
A2: Enum<BloodType> | B2: List<Enum<Ability>> | C2: List<int> | D2: List<float> | E2: List<int>
A3: BloodName | B3: bloodAbility | C3: abilityInitLevel | D3: abilityValue | E3: abilityMaxLevel
A4: Person | B4: Run | C4: 1 | D4: 2| 2 | E4: 20|20
A5: Dragon | B5: Battle | C5: 1 | D5: 2| 2 | E5: 20|20
A6: Undead | B6: Regeneration | C6: 1 | D6: 2| 2 | E6: 20|20
A7: Hollow | B7: Regeneration | C7: 1 | D7: 2| 2 | E7: 20| 20
A8: Beast | B8: Regeneration | C8: 1 | D8: 2| 2 | E8: 20| 20
